2023-02-28 11:58:23,441 ERROR: Exception on /user/ab [GET] [in D:\Esthenos\Learn\venv\lib\site-packages\flask\app.py:1744]
Traceback (most recent call last):
  File "D:\Esthenos\Learn\venv\lib\site-packages\flask\app.py", line 2528, in wsgi_app
    response = self.full_dispatch_request()
  File "D:\Esthenos\Learn\venv\lib\site-packages\flask\app.py", line 1825, in full_dispatch_request
    rv = self.handle_user_exception(e)
  File "D:\Esthenos\Learn\venv\lib\site-packages\flask\app.py", line 1823, in full_dispatch_request
    rv = self.dispatch_request()
  File "D:\Esthenos\Learn\venv\lib\site-packages\flask\app.py", line 1799, in dispatch_request
    return self.ensure_sync(self.view_functions[rule.endpoint])(**view_args)
  File "D:\Esthenos\Learn\venv\lib\site-packages\flask_login\utils.py", line 290, in decorated_view
    return current_app.ensure_sync(func)(*args, **kwargs)
  File "D:\Esthenos\Learn\app\routes.py", line 34, in user
    return render_template('user.html', user=user, posts=posts, form=form)
  File "D:\Esthenos\Learn\venv\lib\site-packages\flask\templating.py", line 147, in render_template
    return _render(app, template, context)
  File "D:\Esthenos\Learn\venv\lib\site-packages\flask\templating.py", line 130, in _render
    rv = template.render(context)
  File "D:\Esthenos\Learn\venv\lib\site-packages\jinja2\environment.py", line 1301, in render
    self.environment.handle_exception()
  File "D:\Esthenos\Learn\venv\lib\site-packages\jinja2\environment.py", line 936, in handle_exception
    raise rewrite_traceback_stack(source=source)
  File "D:\Esthenos\Learn\app\templates\user.html", line 1, in top-level template code
    {% extends "base.html" %}
  File "D:\Esthenos\Learn\app\templates\base.html", line 40, in top-level template code
    {% block content %}{% endblock %}
  File "D:\Esthenos\Learn\app\templates\user.html", line 24, in block 'content'
    <form action="{{ url_for('unfollow', username=user.username) }}" method="post">
  File "D:\Esthenos\Learn\venv\lib\site-packages\flask\app.py", line 2034, in url_for
    return self.handle_url_build_error(error, endpoint, values)
  File "D:\Esthenos\Learn\venv\lib\site-packages\flask\app.py", line 2023, in url_for
    rv = url_adapter.build(  # type: ignore[union-attr]
  File "D:\Esthenos\Learn\venv\lib\site-packages\werkzeug\routing\map.py", line 917, in build
    raise BuildError(endpoint, values, method, self)
werkzeug.routing.exceptions.BuildError: Could not build url for endpoint 'unfollow' with values ['username']. Did you mean 'follow' instead?
2023-02-28 11:58:43,224 ERROR: Exception on /user/ab [GET] [in D:\Esthenos\Learn\venv\lib\site-packages\flask\app.py:1744]
Traceback (most recent call last):
  File "D:\Esthenos\Learn\venv\lib\site-packages\flask\app.py", line 2528, in wsgi_app
    response = self.full_dispatch_request()
  File "D:\Esthenos\Learn\venv\lib\site-packages\flask\app.py", line 1825, in full_dispatch_request
    rv = self.handle_user_exception(e)
  File "D:\Esthenos\Learn\venv\lib\site-packages\flask\app.py", line 1823, in full_dispatch_request
    rv = self.dispatch_request()
  File "D:\Esthenos\Learn\venv\lib\site-packages\flask\app.py", line 1799, in dispatch_request
    return self.ensure_sync(self.view_functions[rule.endpoint])(**view_args)
  File "D:\Esthenos\Learn\venv\lib\site-packages\flask_login\utils.py", line 290, in decorated_view
    return current_app.ensure_sync(func)(*args, **kwargs)
  File "D:\Esthenos\Learn\app\routes.py", line 34, in user
    return render_template('user.html', user=user, posts=posts, form=form)
  File "D:\Esthenos\Learn\venv\lib\site-packages\flask\templating.py", line 147, in render_template
    return _render(app, template, context)
  File "D:\Esthenos\Learn\venv\lib\site-packages\flask\templating.py", line 130, in _render
    rv = template.render(context)
  File "D:\Esthenos\Learn\venv\lib\site-packages\jinja2\environment.py", line 1301, in render
    self.environment.handle_exception()
  File "D:\Esthenos\Learn\venv\lib\site-packages\jinja2\environment.py", line 936, in handle_exception
    raise rewrite_traceback_stack(source=source)
  File "D:\Esthenos\Learn\app\templates\user.html", line 1, in top-level template code
    {% extends "base.html" %}
  File "D:\Esthenos\Learn\app\templates\base.html", line 40, in top-level template code
    {% block content %}{% endblock %}
  File "D:\Esthenos\Learn\app\templates\user.html", line 24, in block 'content'
    <form action="{{ url_for('unfollow', username=user.username) }}" method="post">
  File "D:\Esthenos\Learn\venv\lib\site-packages\flask\app.py", line 2034, in url_for
    return self.handle_url_build_error(error, endpoint, values)
  File "D:\Esthenos\Learn\venv\lib\site-packages\flask\app.py", line 2023, in url_for
    rv = url_adapter.build(  # type: ignore[union-attr]
  File "D:\Esthenos\Learn\venv\lib\site-packages\werkzeug\routing\map.py", line 917, in build
    raise BuildError(endpoint, values, method, self)
werkzeug.routing.exceptions.BuildError: Could not build url for endpoint 'unfollow' with values ['username']. Did you mean 'follow' instead?
2023-02-28 12:04:36,309 INFO: Microblog startup [in D:\Esthenos\Learn\app\__init__.py:44]
2023-02-28 13:12:06,992 INFO: Microblog startup [in D:\Esthenos\Learn\app\__init__.py:44]
2023-02-28 19:22:40,627 INFO: Microblog startup [in D:\Esthenos\Learn\app\__init__.py:45]
2023-02-28 19:24:27,131 INFO: Microblog startup [in D:\Esthenos\Learn\app\__init__.py:45]
2023-02-28 19:24:34,276 ERROR: Exception on /login [GET] [in D:\Esthenos\Learn\venv\lib\site-packages\flask\app.py:1744]
Traceback (most recent call last):
  File "D:\Esthenos\Learn\venv\lib\site-packages\flask\app.py", line 2528, in wsgi_app
    response = self.full_dispatch_request()
  File "D:\Esthenos\Learn\venv\lib\site-packages\flask\app.py", line 1825, in full_dispatch_request
    rv = self.handle_user_exception(e)
  File "D:\Esthenos\Learn\venv\lib\site-packages\flask\app.py", line 1823, in full_dispatch_request
    rv = self.dispatch_request()
  File "D:\Esthenos\Learn\venv\lib\site-packages\flask\app.py", line 1799, in dispatch_request
    return self.ensure_sync(self.view_functions[rule.endpoint])(**view_args)
  File "D:\Esthenos\Learn\app\routes.py", line 84, in login
    return render_template('login.html', title='Sign In', form=form)
  File "D:\Esthenos\Learn\venv\lib\site-packages\flask\templating.py", line 147, in render_template
    return _render(app, template, context)
  File "D:\Esthenos\Learn\venv\lib\site-packages\flask\templating.py", line 130, in _render
    rv = template.render(context)
  File "D:\Esthenos\Learn\venv\lib\site-packages\jinja2\environment.py", line 1301, in render
    self.environment.handle_exception()
  File "D:\Esthenos\Learn\venv\lib\site-packages\jinja2\environment.py", line 936, in handle_exception
    raise rewrite_traceback_stack(source=source)
  File "D:\Esthenos\Learn\app\templates\login.html", line 1, in top-level template code
    {% extends "base.html" %}
  File "D:\Esthenos\Learn\app\templates\base.html", line 41, in top-level template code
    {% block content %}{% endblock %}
  File "D:\Esthenos\Learn\app\templates\login.html", line 24, in block 'content'
    <a href="{{ url_for('reset_password_request') }}">Click to Reset It</a>
  File "D:\Esthenos\Learn\venv\lib\site-packages\flask\app.py", line 2034, in url_for
    return self.handle_url_build_error(error, endpoint, values)
  File "D:\Esthenos\Learn\venv\lib\site-packages\flask\app.py", line 2023, in url_for
    rv = url_adapter.build(  # type: ignore[union-attr]
  File "D:\Esthenos\Learn\venv\lib\site-packages\werkzeug\routing\map.py", line 917, in build
    raise BuildError(endpoint, values, method, self)
werkzeug.routing.exceptions.BuildError: Could not build url for endpoint 'reset_password_request'. Did you mean 'reset_password' instead?
2023-02-28 19:29:12,686 INFO: Microblog startup [in D:\Esthenos\Learn\app\__init__.py:45]
2023-02-28 19:29:21,657 INFO: Microblog startup [in D:\Esthenos\Learn\app\__init__.py:45]
